<?xml version="1.0" ?>
<!-- =================================================================================== -->
<!-- |    This document was autogenerated by xacro from /root/ros_ws/install/ur_description/share/ur_description/urdf/ur.urdf.xacro | -->
<!-- |    EDITING THIS FILE BY HAND IS NOT RECOMMENDED                                 | -->
<!-- =================================================================================== -->
<robot name="ur5e">
    <!-- create link fixed to the "world" -->
    <link name="world"/>
    <!-- links -  main serial chain -->
    <link name="base_link"/>
    <link name="base_link_inertia">
        <visual>
            <origin rpy="0 0 3.141592653589793" xyz="0 0 0"/>
            <geometry>
                <mesh filename="package://meshes/ur5e/visual/base.dae"/>
            </geometry>
        </visual>
        <collision>
            <origin rpy="0 0 3.141592653589793" xyz="0 0 0"/>
            <geometry>
                <mesh filename="package://meshes/ur5e/collision/base.stl"/>
            </geometry>
        </collision>
        <inertial>
            <mass value="4.0"/>
            <origin rpy="0 0 0" xyz="0 0 0"/>
            <inertia ixx="0.00443333156" ixy="0.0" ixz="0.0" iyy="0.00443333156" iyz="0.0" izz="0.0072"/>
        </inertial>
    </link>
    <link name="shoulder_link">
        <visual>
            <origin rpy="0 0 3.141592653589793" xyz="0 0 0"/>
            <geometry>
                <mesh filename="package://meshes/ur5e/visual/shoulder.dae"/>
            </geometry>
        </visual>
        <collision>
            <origin rpy="0 0 3.141592653589793" xyz="0 0 0"/>
            <geometry>
                <mesh filename="package://meshes/ur5e/collision/shoulder.stl"/>
            </geometry>
        </collision>
        <inertial>
            <mass value="3.7"/>
            <origin rpy="0 0 0" xyz="0 0 0"/>
            <inertia ixx="0.010267495893" ixy="0.0" ixz="0.0" iyy="0.010267495893" iyz="0.0" izz="0.00666"/>
        </inertial>
    </link>
    <link name="upper_arm_link">
        <visual>
            <origin rpy="1.5707963267948966 0 -1.5707963267948966" xyz="0 0 0.138"/>
            <geometry>
                <mesh filename="package://meshes/ur5e/visual/upperarm.dae"/>
            </geometry>
        </visual>
        <collision>
            <origin rpy="1.5707963267948966 0 -1.5707963267948966" xyz="0 0 0.138"/>
            <geometry>
                <mesh filename="package://meshes/ur5e/collision/upperarm.stl"/>
            </geometry>
        </collision>
        <inertial>
            <mass value="8.393"/>
            <origin rpy="0 1.5707963267948966 0" xyz="-0.2125 0.0 0.138"/>
            <inertia ixx="0.1338857818623325" ixy="0.0" ixz="0.0" iyy="0.1338857818623325" iyz="0.0" izz="0.0151074"/>
        </inertial>
    </link>
    <link name="forearm_link">
        <visual>
            <origin rpy="1.5707963267948966 0 -1.5707963267948966" xyz="0 0 0.007"/>
            <geometry>
                <mesh filename="package://meshes/ur5e/visual/forearm.dae"/>
            </geometry>
        </visual>
        <collision>
            <origin rpy="1.5707963267948966 0 -1.5707963267948966" xyz="0 0 0.007"/>
            <geometry>
                <mesh filename="package://meshes/ur5e/collision/forearm.stl"/>
            </geometry>
        </collision>
        <inertial>
            <mass value="2.275"/>
            <origin rpy="0 1.5707963267948966 0" xyz="-0.1961 0.0 0.007"/>
            <inertia ixx="0.031209355099586295" ixy="0.0" ixz="0.0" iyy="0.031209355099586295" iyz="0.0" izz="0.004095"/>
        </inertial>
    </link>
    <link name="wrist_1_link">
        <visual>
            <origin rpy="1.5707963267948966 0 0" xyz="0 0 -0.127"/>
            <geometry>
                <mesh filename="package://meshes/ur5e/visual/wrist1.dae"/>
            </geometry>
        </visual>
        <collision>
            <origin rpy="1.5707963267948966 0 0" xyz="0 0 -0.127"/>
            <geometry>
                <mesh filename="package://meshes/ur5e/collision/wrist1.stl"/>
            </geometry>
        </collision>
        <inertial>
            <mass value="1.219"/>
            <origin rpy="0 0 0" xyz="0 0 0"/>
            <inertia ixx="0.0025598989760400002" ixy="0.0" ixz="0.0" iyy="0.0025598989760400002" iyz="0.0" izz="0.0021942"/>
        </inertial>
    </link>
    <link name="wrist_2_link">
        <visual>
            <origin rpy="0 0 0" xyz="0 0 -0.0997"/>
            <geometry>
                <mesh filename="package://meshes/ur5e/visual/wrist2.dae"/>
            </geometry>
        </visual>
        <collision>
            <origin rpy="0 0 0" xyz="0 0 -0.0997"/>
            <geometry>
                <mesh filename="package://meshes/ur5e/collision/wrist2.stl"/>
            </geometry>
        </collision>
        <inertial>
            <mass value="1.219"/>
            <origin rpy="0 0 0" xyz="0 0 0"/>
            <inertia ixx="0.0025598989760400002" ixy="0.0" ixz="0.0" iyy="0.0025598989760400002" iyz="0.0" izz="0.0021942"/>
        </inertial>
    </link>
    <link name="wrist_3_link">
        <visual>
            <origin rpy="1.5707963267948966 0 0" xyz="0 0 -0.0989"/>
            <geometry>
                <mesh filename="package://meshes/ur5e/visual/wrist3.dae"/>
            </geometry>
        </visual>
        <collision>
            <origin rpy="1.5707963267948966 0 0" xyz="0 0 -0.0989"/>
            <geometry>
                <mesh filename="package://meshes/ur5e/collision/wrist3.stl"/>
            </geometry>
        </collision>
        <inertial>
            <mass value="0.1879"/>
            <origin rpy="0 0 0" xyz="0.0 0.0 -0.0229"/>
            <inertia ixx="9.890410052167731e-05" ixy="0.0" ixz="0.0" iyy="9.890410052167731e-05" iyz="0.0" izz="0.0001321171875"/>
        </inertial>
    </link>
    <!-- base_joint fixes base_link to the environment -->
    <joint name="base_joint" type="fixed">
        <origin rpy="0 0 0" xyz="0 0 0"/>
        <parent link="world"/>
        <child link="base_link"/>
    </joint>
    <!-- joints - main serial chain -->
    <joint name="base_link-base_link_inertia" type="fixed">
        <parent link="base_link"/>
        <child link="base_link_inertia"/>
        <!-- 'base_link' is REP-103 aligned (so X+ forward), while the internal
            frames of the robot/controller have X+ pointing backwards.
            Use the joint between 'base_link' and 'base_link_inertia' (a dummy
            link/frame) to introduce the necessary rotation over Z (of pi rad).
        -->
        <origin rpy="0 0 3.141592653589793" xyz="0 0 0"/>
    </joint>
    <joint name="shoulder_pan_joint" type="revolute">
        <parent link="base_link_inertia"/>
        <child link="shoulder_link"/>
        <origin rpy="0 0 0" xyz="0 0 0.1625"/>
        <axis xyz="0 0 1"/>
        <limit effort="150.0" lower="-6.283185307179586" upper="6.283185307179586" velocity="3.141592653589793"/>
        <safety_controller k_position="20" k_velocity="0.0" soft_lower_limit="-6.133185307179586" soft_upper_limit="6.133185307179586"/>
        <dynamics damping="0" friction="0"/>
    </joint>
    <joint name="shoulder_lift_joint" type="revolute">
        <parent link="shoulder_link"/>
        <child link="upper_arm_link"/>
        <origin rpy="1.570796327 0 0" xyz="0 0 0"/>
        <axis xyz="0 0 1"/>
        <limit effort="150.0" lower="-6.283185307179586" upper="6.283185307179586" velocity="3.141592653589793"/>
        <safety_controller k_position="20" k_velocity="0.0" soft_lower_limit="-6.133185307179586" soft_upper_limit="6.133185307179586"/>
        <dynamics damping="0" friction="0"/>
    </joint>
    <joint name="elbow_joint" type="revolute">
        <parent link="upper_arm_link"/>
        <child link="forearm_link"/>
        <origin rpy="0 0 0" xyz="-0.425 0 0"/>
        <axis xyz="0 0 1"/>
        <limit effort="150.0" lower="-3.141592653589793" upper="3.141592653589793" velocity="3.141592653589793"/>
        <safety_controller k_position="20" k_velocity="0.0" soft_lower_limit="-2.991592653589793" soft_upper_limit="2.991592653589793"/>
        <dynamics damping="0" friction="0"/>
    </joint>
    <joint name="wrist_1_joint" type="revolute">
        <parent link="forearm_link"/>
        <child link="wrist_1_link"/>
        <origin rpy="0 0 0" xyz="-0.3922 0 0.1333"/>
        <axis xyz="0 0 1"/>
        <limit effort="28.0" lower="-6.283185307179586" upper="6.283185307179586" velocity="3.141592653589793"/>
        <safety_controller k_position="20" k_velocity="0.0" soft_lower_limit="-6.133185307179586" soft_upper_limit="6.133185307179586"/>
        <dynamics damping="0" friction="0"/>
    </joint>
    <joint name="wrist_2_joint" type="revolute">
        <parent link="wrist_1_link"/>
        <child link="wrist_2_link"/>
        <origin rpy="1.570796327 0 0" xyz="0 -0.0997 -2.044881182297852e-11"/>
        <axis xyz="0 0 1"/>
        <limit effort="28.0" lower="-6.283185307179586" upper="6.283185307179586" velocity="3.141592653589793"/>
        <safety_controller k_position="20" k_velocity="0.0" soft_lower_limit="-6.133185307179586" soft_upper_limit="6.133185307179586"/>
        <dynamics damping="0" friction="0"/>
    </joint>
    <joint name="wrist_3_joint" type="revolute">
        <parent link="wrist_2_link"/>
        <child link="wrist_3_link"/>
        <origin rpy="1.570796326589793 3.141592653589793 3.141592653589793" xyz="0 0.0996 -2.042830148012698e-11"/>
        <axis xyz="0 0 1"/>
        <limit effort="28.0" lower="-6.283185307179586" upper="6.283185307179586" velocity="3.141592653589793"/>
        <safety_controller k_position="20" k_velocity="0.0" soft_lower_limit="-6.133185307179586" soft_upper_limit="6.133185307179586"/>
        <dynamics damping="0" friction="0"/>
    </joint>
    <link name="ft_frame"/>
    <joint name="wrist_3_link-ft_frame" type="fixed">
        <parent link="wrist_3_link"/>
        <child link="ft_frame"/>
        <origin rpy="3.141592653589793 0 0" xyz="0 0 0"/>
    </joint>
    <!-- ROS-Industrial 'base' frame - base_link to UR 'Base' Coordinates transform -->
    <link name="base"/>
    <joint name="base_link-base_fixed_joint" type="fixed">
        <!-- Note the rotation over Z of pi radians - as base_link is REP-103
            aligned (i.e., has X+ forward, Y+ left and Z+ up), this is needed
            to correctly align 'base' with the 'Base' coordinate system of
            the UR controller.
        -->
        <origin rpy="0 0 3.141592653589793" xyz="0 0 0"/>
        <parent link="base_link"/>
        <child link="base"/>
    </joint>
    <!-- ROS-Industrial 'flange' frame - attachment point for EEF models -->
    <link name="flange"/>
    <joint name="wrist_3-flange" type="fixed">
        <parent link="wrist_3_link"/>
        <child link="flange"/>
        <origin rpy="0 -1.5707963267948966 -1.5707963267948966" xyz="0 0 0"/>
    </joint>
    <!-- ROS-Industrial 'tool0' frame - all-zeros tool frame -->
    <link name="tool0"/>
    <joint name="flange-tool0" type="fixed">
        <!-- default toolframe - X+ left, Y+ up, Z+ front -->
        <origin rpy="1.5707963267948966 0 1.5707963267948966" xyz="0 0 0"/>
        <parent link="flange"/>
        <child link="tool0"/>
    </joint>
</robot>
